Workbook

Sheet Dashboard

Sheet Product List
A1: Sr no. | B1: Product ID | C1: Product Name | D1: Category | E1: Supplier Name | F1: Current Stock | G1: Reorder Level | H1: Status
A2: 1 | B2: =IF(D2="","",IF(D2>0,VLOOKUP(D2,Category!$A$2:$B$31,2,FALSE),"")&"-"&TEXT(COUNTIF('Product List'!$D$2:'Product List'!D2,'Product List'!D2),"000")) -> TB-001 | C2: JW PIE Mini Hana - Light Brown | D2: Tote bag | E2: Abdur Rehman | F2: =Sheet4!G2 -> 1 | G2: 0 | H2: =IF(OR(F2="",G2=""),"",IF(F2<=0,"Out of Stock",IF(F2<=G2,"Low on Stock","In Stock"))) -> In Stock
A3: =IF(C3>0,A2+1,"") -> 2 | B3: =IF(D3="","",IF(D3>0,VLOOKUP(D3,Category!$A$2:$B$31,2,FALSE),"")&"-"&TEXT(COUNTIF('Product List'!$D$2:'Product List'!D3,'Product List'!D3),"000")) -> TB-002 | C3: JW PIE Mini Hana - Black | D3: Tote bag | E3: Abdur Rehman | F3: =Sheet4!G3 -> 0 | G3: 0 | H3: =IF(OR(F3="",G3=""),"",IF(F3<=0,"Out of Stock",IF(F3<=G3,"Low on Stock","In Stock"))) -> Out of Stock
A4: =IF(C4>0,A3+1,"") -> 3 | B4: =IF(D4="","",IF(D4>0,VLOOKUP(D4,Category!$A$2:$B$31,2,FALSE),"")&"-"&TEXT(COUNTIF('Product List'!$D$2:'Product List'!D4,'Product List'!D4),"000")) -> TB-003 | C4: JW PIE Elora Woven - Black | D4: Tote bag | E4: Abdur Rehman | F4: =Sheet4!G4 -> 1 | G4: 0 | H4: =IF(OR(F4="",G4=""),"",IF(F4<=0,"Out of Stock",IF(F4<=G4,"Low on Stock","In Stock"))) -> In Stock
A5: =IF(C5>0,A4+1,"") -> 4 | B5: =IF(D5="","",IF(D5>0,VLOOKUP(D5,Category!$A$2:$B$31,2,FALSE),"")&"-"&TEXT(COUNTIF('Product List'!$D$2:'Product List'!D5,'Product List'!D5),"000")) -> TB-004 | C5: JW PIE Elora Woven - Brown | D5: Tote bag | E5: Abdur Rehman | F5: =Sheet4!G5 -> 1 | G5: 0 | H5: =IF(OR(F5="",G5=""),"",IF(F5<=0,"Out of Stock",IF(F5<=G5,"Low on Stock","In Stock"))) -> In Stock
A6: =IF(C6>0,A5+1,"") | B6: =IF(D6="","",IF(D6>0,VLOOKUP(D6,Category!$A$2:$B$31,2,FALSE),"")&"-"&TEXT(COUNTIF('Product List'!$D$2:'Product List'!D6,'Product List'!D6),"000")) | F6: =Sheet4!G6 | H6: =IF(OR(F6="",G6=""),"",IF(F6<=0,"Out of Stock",IF(F6<=G6,"Low on Stock","In Stock")))
A7: =IF(C7>0,A6+1,"") | B7: =IF(D7="","",IF(D7>0,VLOOKUP(D7,Category!$A$2:$B$31,2,FALSE),"")&"-"&TEXT(COUNTIF('Product List'!$D$2:'Product List'!D7,'Product List'!D7),"000")) | F7: =Sheet4!G7 | H7: =IF(OR(F7="",G7=""),"",IF(F7<=0,"Out of Stock",IF(F7<=G7,"Low on Stock","In Stock")))
A8: =IF(C8>0,A7+1,"") | B8: =IF(D8="","",IF(D8>0,VLOOKUP(D8,Category!$A$2:$B$31,2,FALSE),"")&"-"&TEXT(COUNTIF('Product List'!$D$2:'Product List'!D8,'Product List'!D8),"000")) | F8: =Sheet4!G8 | H8: =IF(OR(F8="",G8=""),"",IF(F8<=0,"Out of Stock",IF(F8<=G8,"Low on Stock","In Stock")))
A9: =IF(C9>0,A8+1,"") | B9: =IF(D9="","",IF(D9>0,VLOOKUP(D9,Category!$A$2:$B$31,2,FALSE),"")&"-"&TEXT(COUNTIF('Product List'!$D$2:'Product List'!D9,'Product List'!D9),"000")) | F9: =Sheet4!G9 | H9: =IF(OR(F9="",G9=""),"",IF(F9<=0,"Out of Stock",IF(F9<=G9,"Low on Stock","In Stock")))
A10: =IF(C10>0,A9+1,"") | B10: =IF(D10="","",IF(D10>0,VLOOKUP(D10,Category!$A$2:$B$31,2,FALSE),"")&"-"&TEXT(COUNTIF('Product List'!$D$2:'Product List'!D10,'Product List'!D10),"000")) | F10: =Sheet4!G10 | H10: =IF(OR(F10="",G10=""),"",IF(F10<=0,"Out of Stock",IF(F10<=G10,"Low on Stock","In Stock")))
A11: =IF(C11>0,A10+1,"") | B11: =IF(D11="","",IF(D11>0,VLOOKUP(D11,Category!$A$2:$B$31,2,FALSE),"")&"-"&TEXT(COUNTIF('Product List'!$D$2:'Product List'!D11,'Product List'!D11),"000")) | F11: =Sheet4!G11 | H11: =IF(OR(F11="",G11=""),"",IF(F11<=0,"Out of Stock",IF(F11<=G11,"Low on Stock","In Stock")))
A12: =IF(C12>0,A11+1,"") | B12: =IF(D12="","",IF(D12>0,VLOOKUP(D12,Category!$A$2:$B$31,2,FALSE),"")&"-"&TEXT(COUNTIF('Product List'!$D$2:'Product List'!D12,'Product List'!D12),"000")) | F12: =Sheet4!G12 | H12: =IF(OR(F12="",G12=""),"",IF(F12<=0,"Out of Stock",IF(F12<=G12,"Low on Stock","In Stock")))
A13: =IF(C13>0,A12+1,"") | B13: =IF(D13="","",IF(D13>0,VLOOKUP(D13,Category!$A$2:$B$31,2,FALSE),"")&"-"&TEXT(COUNTIF('Product List'!$D$2:'Product List'!D13,'Product List'!D13),"000")) | F13: =Sheet4!G13 | H13: =IF(OR(F13="",G13=""),"",IF(F13<=0,"Out of Stock",IF(F13<=G13,"Low on Stock","In Stock")))
A14: =IF(C14>0,A13+1,"") | B14: =IF(D14="","",IF(D14>0,VLOOKUP(D14,Category!$A$2:$B$31,2,FALSE),"")&"-"&TEXT(COUNTIF('Product List'!$D$2:'Product List'!D14,'Product List'!D14),"000")) | F14: =Sheet4!G14 | H14: =IF(OR(F14="",G14=""),"",IF(F14<=0,"Out of Stock",IF(F14<=G14,"Low on Stock","In Stock")))
A15: =IF(C15>0,A14+1,"") | B15: =IF(D15="","",IF(D15>0,VLOOKUP(D15,Category!$A$2:$B$31,2,FALSE),"")&"-"&TEXT(COUNTIF('Product List'!$D$2:'Product List'!D15,'Product List'!D15),"000")) | F15: =Sheet4!G15 | H15: =IF(OR(F15="",G15=""),"",IF(F15<=0,"Out of Stock",IF(F15<=G15,"Low on Stock","In Stock")))
A16: =IF(C16>0,A15+1,"") | B16: =IF(D16="","",IF(D16>0,VLOOKUP(D16,Category!$A$2:$B$31,2,FALSE),"")&"-"&TEXT(COUNTIF('Product List'!$D$2:'Product List'!D16,'Product List'!D16),"000")) | F16: =Sheet4!G16 | H16: =IF(OR(F16="",G16=""),"",IF(F16<=0,"Out of Stock",IF(F16<=G16,"Low on Stock","In Stock")))
A17: =IF(C17>0,A16+1,"") | B17: =IF(D17="","",IF(D17>0,VLOOKUP(D17,Category!$A$2:$B$31,2,FALSE),"")&"-"&TEXT(COUNTIF('Product List'!$D$2:'Product List'!D17,'Product List'!D17),"000")) | F17: =Sheet4!G17 | H17: =IF(OR(F17="",G17=""),"",IF(F17<=0,"Out of Stock",IF(F17<=G17,"Low on Stock","In Stock")))
... A596: =IF(C596>0,A595+1,"") | B596: =IF(D596="","",IF(D596>0,VLOOKUP(D596,Category!$A$2:$B$31,2,FALSE),"")&"-"&TEXT(COUNTIF('Product List'!$D$2:'Product List'!D596,'Product List'!D596),"000")) | F596: =Sheet4!G596 | H596: =IF(OR(F596="",G596=""),"",IF(F596<=0,"Out of Stock",IF(F596<=G596,"Low on Stock","In Stock")))

Sheet Purchase Record
A1: Sr no. | B1: Date of Purchase | C1: Month | D1: Year | E1: Product Name | F1: Product ID | G1: Quantity Purchased | H1: Cost per Unit | I1: Total Cost | J1: Supplier Name | K1: Payment Method | L1: Payment Status
A2: 1 | B2: 46132 | C2: =IF(B2=0,"",TEXT(B2,"mmmm")) -> April | D2: =IF(B2=0,"",TEXT(B2,"yyyy")) -> 2026 | E2: JW PIE Mini Hana - Light Brown | F2: =IFERROR(VLOOKUP(E2,Category!$D$2:$E$600,2,FALSE),"") -> TB-001 | G2: 1 | H2: 20000 | I2: =IF(H2*G2=0,"",H2*G2) -> 20000 | J2: Abdur Rehman | K2: Online | L2: Paid
A3: =IF(E3>0,A2+1,"") -> 2 | B3: 46132 | C3: =IF(B3=0,"",TEXT(B3,"mmmm")) -> April | D3: =IF(B3=0,"",TEXT(B3,"yyyy")) -> 2026 | E3: JW PIE Mini Hana - Black | F3: =IFERROR(VLOOKUP(E3,Category!$D$2:$E$600,2,FALSE),"") -> TB-002 | G3: 2 | H3: 20000 | I3: =IF(H3*G3=0,"",H3*G3) -> 40000 | J3: Abdur Rehman | K3: Online | L3: Paid
A4: =IF(E4>0,A3+1,"") -> 3 | B4: 46132 | C4: =IF(B4=0,"",TEXT(B4,"mmmm")) -> April | D4: =IF(B4=0,"",TEXT(B4,"yyyy")) -> 2026 | E4: JW PIE Elora Woven - Black | F4: =IFERROR(VLOOKUP(E4,Category!$D$2:$E$600,2,FALSE),"") -> TB-003 | G4: 2 | H4: 25000 | I4: =IF(H4*G4=0,"",H4*G4) -> 50000 | J4: Abdur Rehman | K4: Online | L4: Paid
A5: =IF(E5>0,A4+1,"") -> 4 | B5: 46132 | C5: =IF(B5=0,"",TEXT(B5,"mmmm")) -> April | D5: =IF(B5=0,"",TEXT(B5,"yyyy")) -> 2026 | E5: JW PIE Elora Woven - Brown | F5: =IFERROR(VLOOKUP(E5,Category!$D$2:$E$600,2,FALSE),"") -> TB-004 | G5: 2 | H5: 25000 | I5: =IF(H5*G5=0,"",H5*G5) -> 50000 | J5: Abdur Rehman | K5: Online | L5: Paid
A6: =IF(E6>0,A5+1,"") | C6: =IF(B6=0,"",TEXT(B6,"mmmm")) | D6: =IF(B6=0,"",TEXT(B6,"yyyy")) | F6: =IFERROR(VLOOKUP(E6,Category!$D$2:$E$600,2,FALSE),"") | I6: =IF(H6*G6=0,"",H6*G6)
A7: =IF(E7>0,A6+1,"") | C7: =IF(B7=0,"",TEXT(B7,"mmmm")) | D7: =IF(B7=0,"",TEXT(B7,"yyyy")) | F7: =IFERROR(VLOOKUP(E7,Category!$D$2:$E$600,2,FALSE),"") | I7: =IF(H7*G7=0,"",H7*G7)
A8: =IF(E8>0,A7+1,"") | C8: =IF(B8=0,"",TEXT(B8,"mmmm")) | D8: =IF(B8=0,"",TEXT(B8,"yyyy")) | F8: =IFERROR(VLOOKUP(E8,Category!$D$2:$E$600,2,FALSE),"") | I8: =IF(H8*G8=0,"",H8*G8)
A9: =IF(E9>0,A8+1,"") | C9: =IF(B9=0,"",TEXT(B9,"mmmm")) | D9: =IF(B9=0,"",TEXT(B9,"yyyy")) | F9: =IFERROR(VLOOKUP(E9,Category!$D$2:$E$600,2,FALSE),"") | I9: =IF(H9*G9=0,"",H9*G9)
A10: =IF(E10>0,A9+1,"") | C10: =IF(B10=0,"",TEXT(B10,"mmmm")) | D10: =IF(B10=0,"",TEXT(B10,"yyyy")) | F10: =IFERROR(VLOOKUP(E10,Category!$D$2:$E$600,2,FALSE),"") | I10: =IF(H10*G10=0,"",H10*G10)
A11: =IF(E11>0,A10+1,"") | C11: =IF(B11=0,"",TEXT(B11,"mmmm")) | D11: =IF(B11=0,"",TEXT(B11,"yyyy")) | F11: =IFERROR(VLOOKUP(E11,Category!$D$2:$E$600,2,FALSE),"") | I11: =IF(H11*G11=0,"",H11*G11)
A12: =IF(E12>0,A11+1,"") | C12: =IF(B12=0,"",TEXT(B12,"mmmm")) | D12: =IF(B12=0,"",TEXT(B12,"yyyy")) | F12: =IFERROR(VLOOKUP(E12,Category!$D$2:$E$600,2,FALSE),"") | I12: =IF(H12*G12=0,"",H12*G12)
A13: =IF(E13>0,A12+1,"") | C13: =IF(B13=0,"",TEXT(B13,"mmmm")) | D13: =IF(B13=0,"",TEXT(B13,"yyyy")) | F13: =IFERROR(VLOOKUP(E13,Category!$D$2:$E$600,2,FALSE),"") | I13: =IF(H13*G13=0,"",H13*G13)
A14: =IF(E14>0,A13+1,"") | C14: =IF(B14=0,"",TEXT(B14,"mmmm")) | D14: =IF(B14=0,"",TEXT(B14,"yyyy")) | F14: =IFERROR(VLOOKUP(E14,Category!$D$2:$E$600,2,FALSE),"") | I14: =IF(H14*G14=0,"",H14*G14)
A15: =IF(E15>0,A14+1,"") | C15: =IF(B15=0,"",TEXT(B15,"mmmm")) | D15: =IF(B15=0,"",TEXT(B15,"yyyy")) | F15: =IFERROR(VLOOKUP(E15,Category!$D$2:$E$600,2,FALSE),"") | I15: =IF(H15*G15=0,"",H15*G15)
A16: =IF(E16>0,A15+1,"") | C16: =IF(B16=0,"",TEXT(B16,"mmmm")) | D16: =IF(B16=0,"",TEXT(B16,"yyyy")) | F16: =IFERROR(VLOOKUP(E16,Category!$D$2:$E$600,2,FALSE),"") | I16: =IF(H16*G16=0,"",H16*G16)
A17: =IF(E17>0,A16+1,"") | C17: =IF(B17=0,"",TEXT(B17,"mmmm")) | D17: =IF(B17=0,"",TEXT(B17,"yyyy")) | F17: =IFERROR(VLOOKUP(E17,Category!$D$2:$E$600,2,FALSE),"") | I17: =IF(H17*G17=0,"",H17*G17)
... A995: =IF(E995>0,A994+1,"") | C995: =IF(B995=0,"",TEXT(B995,"mmmm")) | D995: =IF(B995=0,"",TEXT(B995,"yyyy")) | F995: =IFERROR(VLOOKUP(E995,Category!$D$2:$E$600,2,FALSE),"") | I995: =IF(H995*G995=0,"",H995*G995)

Sheet Sales Record
A1: Sr no. | B1: Date | C1: Month | D1: Year | E1: Product Name | F1: Product ID | G1: Cost per Item | H1: Quantity Sold | I1: Selling price per Unit | J1: Advance paid | K1: Advance Received by | L1: Advance transferred to account | M1: Pending Amount | N1: Pending Amount Paid | O1: Total Sales | P1: Customer Name | Q1: Payment Method | R1: Payment Status | S1: Dispatch Status | T1: Profit per Product
A2: =IF(E2>0,1,"") -> 1 | B2: 46246 | C2: =IF(B2=0,"",TEXT(B2,"mmmm")) -> August | D2: =IF(B2=0,"",TEXT(B2,"yyyy")) -> 2026 | E2: JW PIE Mini Hana - Black | F2: =IFERROR(VLOOKUP(E2,Category!$D$2:$E$600,2,FALSE),"") -> TB-002 | G2: 20000 | H2: 1 | I2: 50000 | J2: 45000 | K2: saad | L2: Yes | M2: =IFERROR(IF(O2>0,IF(R2="Paid","",O2-J2),""),"") | N2: =IF(J2>0,IF(R2="Paid",O2-J2,""),"") -> 5000 | O2: =IF(H2*I2=0,"",H2*I2) -> 50000 | P2: Saad | Q2: Advance | R2: Paid | S2: Dispatched | T2: =IF(R2="paid",(H2*I2)-(G2*H2),"") -> 30000
A3: =IF(E3>0,A2+1,"") -> 2 | B3: 46247 | C3: =IF(B3=0,"",TEXT(B3,"mmmm")) -> August | D3: =IF(B3=0,"",TEXT(B3,"yyyy")) -> 2026 | E3: JW PIE Elora Woven - Black | F3: =IFERROR(VLOOKUP(E3,Category!$D$2:$E$600,2,FALSE),"") -> TB-003 | G3: 25000 | H3: 1 | I3: 60000 | J3: 40000 | K3: saad | L3: Yes | M3: =IFERROR(IF(O3>0,IF(R3="Paid","",O3-J3),""),"") | N3: =IF(J3>0,IF(R3="Paid",O3-J3,""),"") -> 20000 | O3: =IF(H3*I3=0,"",H3*I3) -> 60000 | P3: Saba | Q3: Advance | R3: Paid | S3: Dispatched | T3: =IF(R3="paid",(H3*I3)-(G3*H3),"") -> 35000
A4: =IF(E4>0,A3+1,"") -> 3 | B4: 46248 | C4: =IF(B4=0,"",TEXT(B4,"mmmm")) -> August | D4: =IF(B4=0,"",TEXT(B4,"yyyy")) -> 2026 | E4: JW PIE Elora Woven - Brown | F4: =IFERROR(VLOOKUP(E4,Category!$D$2:$E$600,2,FALSE),"") -> TB-004 | G4: 25000 | H4: 1 | I4: 60000 | J4: 40000 | K4: Ali | L4: Yes | M4: =IFERROR(IF(O4>0,IF(R4="Paid","",O4-J4),""),"") | N4: =IF(J4>0,IF(R4="Paid",O4-J4,""),"") -> 20000 | O4: =IF(H4*I4=0,"",H4*I4) -> 60000 | P4: ali | Q4: Advance | R4: Paid | S4: Dispatched | T4: =IF(R4="paid",(H4*I4)-(G4*H4),"") -> 35000
A5: =IF(E5>0,A4+1,"") -> 4 | B5: 46249 | C5: =IF(B5=0,"",TEXT(B5,"mmmm")) -> August | D5: =IF(B5=0,"",TEXT(B5,"yyyy")) -> 2026 | E5: JW PIE Mini Hana - Black | F5: =IFERROR(VLOOKUP(E5,Category!$D$2:$E$600,2,FALSE),"") -> TB-002 | G5: 20000 | H5: 1 | I5: 50000 | J5: 45000 | K5: saad | L5: Yes | M5: =IFERROR(IF(O5>0,IF(R5="Paid","",O5-J5),""),"") -> 5000 | N5: =IF(J5>0,IF(R5="Paid",O5-J5,""),"") | O5: =IF(H5*I5=0,"",H5*I5) -> 50000 | P5: Saba | Q5: Advance | R5: Pending | S5: Dispatched | T5: =IF(R5="paid",(H5*I5)-(G5*H5),"")
A6: =IF(E6>0,A5+1,"") | C6: =IF(B6=0,"",TEXT(B6,"mmmm")) | D6: =IF(B6=0,"",TEXT(B6,"yyyy")) | F6: =IFERROR(VLOOKUP(E6,Category!$D$2:$E$600,2,FALSE),"") | M6: =IFERROR(IF(O6>0,IF(R6="Paid","",O6-J6),""),"") | N6: =IF(J6>0,IF(R6="Paid",O6-J6,""),"") | O6: =IF(H6*I6=0,"",H6*I6) | T6: =IF(R6="paid",(H6*I6)-(G6*H6),"")
A7: =IF(E7>0,A6+1,"") | C7: =IF(B7=0,"",TEXT(B7,"mmmm")) | D7: =IF(B7=0,"",TEXT(B7,"yyyy")) | F7: =IFERROR(VLOOKUP(E7,Category!$D$2:$E$600,2,FALSE),"") | M7: =IFERROR(IF(O7>0,IF(R7="Paid","",O7-J7),""),"") | N7: =IF(J7>0,IF(R7="Paid",O7-J7,""),"") | O7: =IF(H7*I7=0,"",H7*I7) | T7: =IF(R7="paid",(H7*I7)-(G7*H7),"")
A8: =IF(E8>0,A7+1,"") | C8: =IF(B8=0,"",TEXT(B8,"mmmm")) | D8: =IF(B8=0,"",TEXT(B8,"yyyy")) | F8: =IFERROR(VLOOKUP(E8,Category!$D$2:$E$600,2,FALSE),"") | M8: =IFERROR(IF(O8>0,IF(R8="Paid","",O8-J8),""),"") | N8: =IF(J8>0,IF(R8="Paid",O8-J8,""),"") | O8: =IF(H8*I8=0,"",H8*I8) | T8: =IF(R8="paid",(H8*I8)-(G8*H8),"")
A9: =IF(E9>0,A8+1,"") | C9: =IF(B9=0,"",TEXT(B9,"mmmm")) | D9: =IF(B9=0,"",TEXT(B9,"yyyy")) | F9: =IFERROR(VLOOKUP(E9,Category!$D$2:$E$600,2,FALSE),"") | M9: =IFERROR(IF(O9>0,IF(R9="Paid","",O9-J9),""),"") | N9: =IF(J9>0,IF(R9="Paid",O9-J9,""),"") | O9: =IF(H9*I9=0,"",H9*I9) | T9: =IF(R9="paid",(H9*I9)-(G9*H9),"")
A10: =IF(E10>0,A9+1,"") | C10: =IF(B10=0,"",TEXT(B10,"mmmm")) | D10: =IF(B10=0,"",TEXT(B10,"yyyy")) | F10: =IFERROR(VLOOKUP(E10,Category!$D$2:$E$600,2,FALSE),"") | M10: =IFERROR(IF(O10>0,IF(R10="Paid","",O10-J10),""),"") | N10: =IF(J10>0,IF(R10="Paid",O10-J10,""),"") | O10: =IF(H10*I10=0,"",H10*I10) | T10: =IF(R10="paid",(H10*I10)-(G10*H10),"")
A11: =IF(E11>0,A10+1,"") | C11: =IF(B11=0,"",TEXT(B11,"mmmm")) | D11: =IF(B11=0,"",TEXT(B11,"yyyy")) | F11: =IFERROR(VLOOKUP(E11,Category!$D$2:$E$600,2,FALSE),"") | M11: =IFERROR(IF(O11>0,IF(R11="Paid","",O11-J11),""),"") | N11: =IF(J11>0,IF(R11="Paid",O11-J11,""),"") | O11: =IF(H11*I11=0,"",H11*I11) | T11: =IF(R11="paid",(H11*I11)-(G11*H11),"")
A12: =IF(E12>0,A11+1,"") | C12: =IF(B12=0,"",TEXT(B12,"mmmm")) | D12: =IF(B12=0,"",TEXT(B12,"yyyy")) | F12: =IFERROR(VLOOKUP(E12,Category!$D$2:$E$600,2,FALSE),"") | M12: =IFERROR(IF(O12>0,IF(R12="Paid","",O12-J12),""),"") | N12: =IF(J12>0,IF(R12="Paid",O12-J12,""),"") | O12: =IF(H12*I12=0,"",H12*I12) | T12: =IF(R12="paid",(H12*I12)-(G12*H12),"")
A13: =IF(E13>0,A12+1,"") | C13: =IF(B13=0,"",TEXT(B13,"mmmm")) | D13: =IF(B13=0,"",TEXT(B13,"yyyy")) | F13: =IFERROR(VLOOKUP(E13,Category!$D$2:$E$600,2,FALSE),"") | M13: =IFERROR(IF(O13>0,IF(R13="Paid","",O13-J13),""),"") | N13: =IF(J13>0,IF(R13="Paid",O13-J13,""),"") | O13: =IF(H13*I13=0,"",H13*I13) | T13: =IF(R13="paid",(H13*I13)-(G13*H13),"")
A14: =IF(E14>0,A13+1,"") | C14: =IF(B14=0,"",TEXT(B14,"mmmm")) | D14: =IF(B14=0,"",TEXT(B14,"yyyy")) | F14: =IFERROR(VLOOKUP(E14,Category!$D$2:$E$600,2,FALSE),"") | M14: =IFERROR(IF(O14>0,IF(R14="Paid","",O14-J14),""),"") | N14: =IF(J14>0,IF(R14="Paid",O14-J14,""),"") | O14: =IF(H14*I14=0,"",H14*I14) | T14: =IF(R14="paid",(H14*I14)-(G14*H14),"")
A15: =IF(E15>0,A14+1,"") | C15: =IF(B15=0,"",TEXT(B15,"mmmm")) | D15: =IF(B15=0,"",TEXT(B15,"yyyy")) | F15: =IFERROR(VLOOKUP(E15,Category!$D$2:$E$600,2,FALSE),"") | M15: =IFERROR(IF(O15>0,IF(R15="Paid","",O15-J15),""),"") | N15: =IF(J15>0,IF(R15="Paid",O15-J15,""),"") | O15: =IF(H15*I15=0,"",H15*I15) | T15: =IF(R15="paid",(H15*I15)-(G15*H15),"")
A16: =IF(E16>0,A15+1,"") | C16: =IF(B16=0,"",TEXT(B16,"mmmm")) | D16: =IF(B16=0,"",TEXT(B16,"yyyy")) | F16: =IFERROR(VLOOKUP(E16,Category!$D$2:$E$600,2,FALSE),"") | M16: =IFERROR(IF(O16>0,IF(R16="Paid","",O16-J16),""),"") | N16: =IF(J16>0,IF(R16="Paid",O16-J16,""),"") | O16: =IF(H16*I16=0,"",H16*I16) | T16: =IF(R16="paid",(H16*I16)-(G16*H16),"")
A17: =IF(E17>0,A16+1,"") | C17: =IF(B17=0,"",TEXT(B17,"mmmm")) | D17: =IF(B17=0,"",TEXT(B17,"yyyy")) | F17: =IFERROR(VLOOKUP(E17,Category!$D$2:$E$600,2,FALSE),"") | M17: =IFERROR(IF(O17>0,IF(R17="Paid","",O17-J17),""),"") | N17: =IF(J17>0,IF(R17="Paid",O17-J17,""),"") | O17: =IF(H17*I17=0,"",H17*I17) | T17: =IF(R17="paid",(H17*I17)-(G17*H17),"")
... A1496: =IF(E1496>0,A1495+1,"") | C1496: =IF(B1496=0,"",TEXT(B1496,"mmmm")) | D1496: =IF(B1496=0,"",TEXT(B1496,"yyyy")) | F1496: =IFERROR(VLOOKUP(E1496,Category!$D$2:$E$600,2,FALSE),"") | M1496: =IFERROR(IF(O1496>0,IF(R1496="Paid","",O1496-J1496),""),"") | N1496: =IF(J1496>0,IF(R1496="Paid",O1496-J1496,""),"") | O1496: =IF(H1496*I1496=0,"",H1496*I1496) | T1496: =IF(R1496="paid",(H1496*I1496)-(G1496*H1496),"")

Sheet Sales Return
A1: Sr no. | B1: Date | C1: Month | D1: Year | E1: Product Name | F1: Product ID | G1: Quantity Returned | H1: Selling price per Unit | I1: Total Amount Returned | J1: Customer Name | K1: Reason For return
A2: =IF(E2>0,1,"") | C2: =IF(B2=0,"",TEXT(B2,"mmmm")) | D2: =IF(B2=0,"",TEXT(B2,"yyyy")) | F2: =IFERROR(VLOOKUP(E2,Category!$D$2:$E$600,2,FALSE),"") | I2: =IF(G2*H2=0,"",G2*H2)
A3: =IF(E3>0,A2+1,"") | C3: =IF(B3=0,"",TEXT(B3,"mmmm")) | D3: =IF(B3=0,"",TEXT(B3,"yyyy")) | F3: =IFERROR(VLOOKUP(E3,Category!$D$2:$E$600,2,FALSE),"") | I3: =IF(G3*H3=0,"",G3*H3)
A4: =IF(E4>0,A3+1,"") | C4: =IF(B4=0,"",TEXT(B4,"mmmm")) | D4: =IF(B4=0,"",TEXT(B4,"yyyy")) | F4: =IFERROR(VLOOKUP(E4,Category!$D$2:$E$600,2,FALSE),"") | I4: =IF(G4*H4=0,"",G4*H4)
A5: =IF(E5>0,A4+1,"") | C5: =IF(B5=0,"",TEXT(B5,"mmmm")) | D5: =IF(B5=0,"",TEXT(B5,"yyyy")) | F5: =IFERROR(VLOOKUP(E5,Category!$D$2:$E$600,2,FALSE),"") | I5: =IF(G5*H5=0,"",G5*H5)
A6: =IF(E6>0,A5+1,"") | C6: =IF(B6=0,"",TEXT(B6,"mmmm")) | D6: =IF(B6=0,"",TEXT(B6,"yyyy")) | F6: =IFERROR(VLOOKUP(E6,Category!$D$2:$E$600,2,FALSE),"") | I6: =IF(G6*H6=0,"",G6*H6)
A7: =IF(E7>0,A6+1,"") | C7: =IF(B7=0,"",TEXT(B7,"mmmm")) | D7: =IF(B7=0,"",TEXT(B7,"yyyy")) | F7: =IFERROR(VLOOKUP(E7,Category!$D$2:$E$600,2,FALSE),"") | I7: =IF(G7*H7=0,"",G7*H7)
A8: =IF(E8>0,A7+1,"") | C8: =IF(B8=0,"",TEXT(B8,"mmmm")) | D8: =IF(B8=0,"",TEXT(B8,"yyyy")) | F8: =IFERROR(VLOOKUP(E8,Category!$D$2:$E$600,2,FALSE),"") | I8: =IF(G8*H8=0,"",G8*H8)
A9: =IF(E9>0,A8+1,"") | C9: =IF(B9=0,"",TEXT(B9,"mmmm")) | D9: =IF(B9=0,"",TEXT(B9,"yyyy")) | F9: =IFERROR(VLOOKUP(E9,Category!$D$2:$E$600,2,FALSE),"") | I9: =IF(G9*H9=0,"",G9*H9)
A10: =IF(E10>0,A9+1,"") | C10: =IF(B10=0,"",TEXT(B10,"mmmm")) | D10: =IF(B10=0,"",TEXT(B10,"yyyy")) | F10: =IFERROR(VLOOKUP(E10,Category!$D$2:$E$600,2,FALSE),"") | I10: =IF(G10*H10=0,"",G10*H10)
A11: =IF(E11>0,A10+1,"") | C11: =IF(B11=0,"",TEXT(B11,"mmmm")) | D11: =IF(B11=0,"",TEXT(B11,"yyyy")) | F11: =IFERROR(VLOOKUP(E11,Category!$D$2:$E$600,2,FALSE),"") | I11: =IF(G11*H11=0,"",G11*H11)
A12: =IF(E12>0,A11+1,"") | C12: =IF(B12=0,"",TEXT(B12,"mmmm")) | D12: =IF(B12=0,"",TEXT(B12,"yyyy")) | F12: =IFERROR(VLOOKUP(E12,Category!$D$2:$E$600,2,FALSE),"") | I12: =IF(G12*H12=0,"",G12*H12)
A13: =IF(E13>0,A12+1,"") | C13: =IF(B13=0,"",TEXT(B13,"mmmm")) | D13: =IF(B13=0,"",TEXT(B13,"yyyy")) | F13: =IFERROR(VLOOKUP(E13,Category!$D$2:$E$600,2,FALSE),"") | I13: =IF(G13*H13=0,"",G13*H13)
A14: =IF(E14>0,A13+1,"") | C14: =IF(B14=0,"",TEXT(B14,"mmmm")) | D14: =IF(B14=0,"",TEXT(B14,"yyyy")) | F14: =IFERROR(VLOOKUP(E14,Category!$D$2:$E$600,2,FALSE),"") | I14: =IF(G14*H14=0,"",G14*H14)
... A1496: =IF(E1496>0,A1495+1,"") | C1496: =IF(B1496=0,"",TEXT(B1496,"mmmm")) | D1496: =IF(B1496=0,"",TEXT(B1496,"yyyy")) | F1496: =IFERROR(VLOOKUP(E1496,Category!$D$2:$E$600,2,FALSE),"") | I1496: =IF(G1496*H1496=0,"",G1496*H1496)

Sheet Purchase Return
A1: Sr no. | B1: Date | C1: Month | D1: Year | E1: Product Name | F1: Product ID | G1: Quantity Returned | H1: Cost price. per Unit | I1: Total Returned Cost | J1: Supplier Name | K1: Reason For return
A2: =IF(E2>0,1,"") | C2: =IF(B2=0,"",TEXT(B2,"mmmm")) | D2: =IF(B2=0,"",TEXT(B2,"yyyy")) | F2: =IFERROR(VLOOKUP(E2,Category!$D$2:$E$600,2,FALSE),"") | I2: =IF(G2*H2=0,"",G2*H2)
A3: =IF(E3>0,A2+1,"") | C3: =IF(B3=0,"",TEXT(B3,"mmmm")) | D3: =IF(B3=0,"",TEXT(B3,"yyyy")) | F3: =IFERROR(VLOOKUP(E3,Category!$D$2:$E$600,2,FALSE),"") | I3: =IF(G3*H3=0,"",G3*H3)
A4: =IF(E4>0,A3+1,"") | C4: =IF(B4=0,"",TEXT(B4,"mmmm")) | D4: =IF(B4=0,"",TEXT(B4,"yyyy")) | F4: =IFERROR(VLOOKUP(E4,Category!$D$2:$E$600,2,FALSE),"") | I4: =IF(G4*H4=0,"",G4*H4)
A5: =IF(E5>0,A4+1,"") | C5: =IF(B5=0,"",TEXT(B5,"mmmm")) | D5: =IF(B5=0,"",TEXT(B5,"yyyy")) | F5: =IFERROR(VLOOKUP(E5,Category!$D$2:$E$600,2,FALSE),"") | I5: =IF(G5*H5=0,"",G5*H5)
A6: =IF(E6>0,A5+1,"") | C6: =IF(B6=0,"",TEXT(B6,"mmmm")) | D6: =IF(B6=0,"",TEXT(B6,"yyyy")) | F6: =IFERROR(VLOOKUP(E6,Category!$D$2:$E$600,2,FALSE),"") | I6: =IF(G6*H6=0,"",G6*H6)
A7: =IF(E7>0,A6+1,"") | C7: =IF(B7=0,"",TEXT(B7,"mmmm")) | D7: =IF(B7=0,"",TEXT(B7,"yyyy")) | F7: =IFERROR(VLOOKUP(E7,Category!$D$2:$E$600,2,FALSE),"") | I7: =IF(G7*H7=0,"",G7*H7)
A8: =IF(E8>0,A7+1,"") | C8: =IF(B8=0,"",TEXT(B8,"mmmm")) | D8: =IF(B8=0,"",TEXT(B8,"yyyy")) | F8: =IFERROR(VLOOKUP(E8,Category!$D$2:$E$600,2,FALSE),"") | I8: =IF(G8*H8=0,"",G8*H8)
A9: =IF(E9>0,A8+1,"") | C9: =IF(B9=0,"",TEXT(B9,"mmmm")) | D9: =IF(B9=0,"",TEXT(B9,"yyyy")) | F9: =IFERROR(VLOOKUP(E9,Category!$D$2:$E$600,2,FALSE),"") | I9: =IF(G9*H9=0,"",G9*H9)
A10: =IF(E10>0,A9+1,"") | C10: =IF(B10=0,"",TEXT(B10,"mmmm")) | D10: =IF(B10=0,"",TEXT(B10,"yyyy")) | F10: =IFERROR(VLOOKUP(E10,Category!$D$2:$E$600,2,FALSE),"") | I10: =IF(G10*H10=0,"",G10*H10)
A11: =IF(E11>0,A10+1,"") | C11: =IF(B11=0,"",TEXT(B11,"mmmm")) | D11: =IF(B11=0,"",TEXT(B11,"yyyy")) | F11: =IFERROR(VLOOKUP(E11,Category!$D$2:$E$600,2,FALSE),"") | I11: =IF(G11*H11=0,"",G11*H11)
A12: =IF(E12>0,A11+1,"") | C12: =IF(B12=0,"",TEXT(B12,"mmmm")) | D12: =IF(B12=0,"",TEXT(B12,"yyyy")) | F12: =IFERROR(VLOOKUP(E12,Category!$D$2:$E$600,2,FALSE),"") | I12: =IF(G12*H12=0,"",G12*H12)
A13: =IF(E13>0,A12+1,"") | C13: =IF(B13=0,"",TEXT(B13,"mmmm")) | D13: =IF(B13=0,"",TEXT(B13,"yyyy")) | F13: =IFERROR(VLOOKUP(E13,Category!$D$2:$E$600,2,FALSE),"") | I13: =IF(G13*H13=0,"",G13*H13)
A14: =IF(E14>0,A13+1,"") | C14: =IF(B14=0,"",TEXT(B14,"mmmm")) | D14: =IF(B14=0,"",TEXT(B14,"yyyy")) | F14: =IFERROR(VLOOKUP(E14,Category!$D$2:$E$600,2,FALSE),"") | I14: =IF(G14*H14=0,"",G14*H14)
... A1496: =IF(E1496>0,A1495+1,"") | C1496: =IF(B1496=0,"",TEXT(B1496,"mmmm")) | D1496: =IF(B1496=0,"",TEXT(B1496,"yyyy")) | F1496: =IFERROR(VLOOKUP(E1496,Category!$D$2:$E$600,2,FALSE),"") | I1496: =IF(G1496*H1496=0,"",G1496*H1496)

Sheet SocialEXP
A1: Sr # | B1: Date | C1: Month | D1: Year | E1: Category | F1: Detail | G1: Quantity | H1: Cost per Item | I1: Total Cost | J1: Capital left | K1: =Category!R12 -> 0
A2: =IF(E2>0,1,"") -> 1 | B2: 46245 | C2: =IF(B2=0,"",TEXT(B2,"mmmm")) -> August | D2: =IF(B2=0,"",TEXT(B2,"yyyy")) -> 2026 | E2: Ad | F2: Post boost | G2: 1 | H2: 13000 | I2: =IF(G2*H2=0,"",G2*H2) -> 13000
A3: =IF(E3>0,A2+1,"") | C3: =IF(B3=0,"",TEXT(B3,"mmmm")) | D3: =IF(B3=0,"",TEXT(B3,"yyyy")) | I3: =IF(G3*H3=0,"",G3*H3)
A4: =IF(E4>0,A3+1,"") | C4: =IF(B4=0,"",TEXT(B4,"mmmm")) | D4: =IF(B4=0,"",TEXT(B4,"yyyy")) | I4: =IF(G4*H4=0,"",G4*H4)
A5: =IF(E5>0,A4+1,"") | C5: =IF(B5=0,"",TEXT(B5,"mmmm")) | D5: =IF(B5=0,"",TEXT(B5,"yyyy")) | I5: =IF(G5*H5=0,"",G5*H5)
A6: =IF(E6>0,A5+1,"") | C6: =IF(B6=0,"",TEXT(B6,"mmmm")) | D6: =IF(B6=0,"",TEXT(B6,"yyyy")) | I6: =IF(G6*H6=0,"",G6*H6)
A7: =IF(E7>0,A6+1,"") | C7: =IF(B7=0,"",TEXT(B7,"mmmm")) | D7: =IF(B7=0,"",TEXT(B7,"yyyy")) | I7: =IF(G7*H7=0,"",G7*H7)
A8: =IF(E8>0,A7+1,"") | C8: =IF(B8=0,"",TEXT(B8,"mmmm")) | D8: =IF(B8=0,"",TEXT(B8,"yyyy")) | I8: =IF(G8*H8=0,"",G8*H8)
A9: =IF(E9>0,A8+1,"") | C9: =IF(B9=0,"",TEXT(B9,"mmmm")) | D9: =IF(B9=0,"",TEXT(B9,"yyyy")) | I9: =IF(G9*H9=0,"",G9*H9)
A10: =IF(E10>0,A9+1,"") | C10: =IF(B10=0,"",TEXT(B10,"mmmm")) | D10: =IF(B10=0,"",TEXT(B10,"yyyy")) | I10: =IF(G10*H10=0,"",G10*H10)
A11: =IF(E11>0,A10+1,"") | C11: =IF(B11=0,"",TEXT(B11,"mmmm")) | D11: =IF(B11=0,"",TEXT(B11,"yyyy")) | I11: =IF(G11*H11=0,"",G11*H11)
A12: =IF(E12>0,A11+1,"") | C12: =IF(B12=0,"",TEXT(B12,"mmmm")) | D12: =IF(B12=0,"",TEXT(B12,"yyyy")) | I12: =IF(G12*H12=0,"",G12*H12)
A13: =IF(E13>0,A12+1,"") | C13: =IF(B13=0,"",TEXT(B13,"mmmm")) | D13: =IF(B13=0,"",TEXT(B13,"yyyy")) | I13: =IF(G13*H13=0,"",G13*H13)
A14: =IF(E14>0,A13+1,"") | C14: =IF(B14=0,"",TEXT(B14,"mmmm")) | D14: =IF(B14=0,"",TEXT(B14,"yyyy")) | I14: =IF(G14*H14=0,"",G14*H14)
... A1348: =IF(E1348>0,A1347+1,"") | C1348: =IF(B1348=0,"",TEXT(B1348,"mmmm")) | D1348: =IF(B1348=0,"",TEXT(B1348,"yyyy")) | I1348: =IF(G1348*H1348=0,"",G1348*H1348)

Sheet Ads investment
A1: Sr # | B1: Date | C1: Month | D1: Year | E1: Detail | F1: Invested amount
A2: =IF(E2>0,1,"") -> 1 | B2: 46245 | C2: =IF(B2=0,"",TEXT(B2,"mmmm")) -> August | D2: =IF(B2=0,"",TEXT(B2,"yyyy")) -> 2026 | E2: Ad money left form previous investment | F2: 13000
A3: =IF(E3>0,A2+1,"") | C3: =IF(B3=0,"",TEXT(B3,"mmmm")) | D3: =IF(B3=0,"",TEXT(B3,"yyyy"))
A4: =IF(E4>0,A3+1,"") | C4: =IF(B4=0,"",TEXT(B4,"mmmm")) | D4: =IF(B4=0,"",TEXT(B4,"yyyy"))
A5: =IF(E5>0,A4+1,"") | C5: =IF(B5=0,"",TEXT(B5,"mmmm")) | D5: =IF(B5=0,"",TEXT(B5,"yyyy"))
A6: =IF(E6>0,A5+1,"") | C6: =IF(B6=0,"",TEXT(B6,"mmmm")) | D6: =IF(B6=0,"",TEXT(B6,"yyyy"))
A7: =IF(E7>0,A6+1,"") | C7: =IF(B7=0,"",TEXT(B7,"mmmm")) | D7: =IF(B7=0,"",TEXT(B7,"yyyy"))
A8: =IF(E8>0,A7+1,"") | C8: =IF(B8=0,"",TEXT(B8,"mmmm")) | D8: =IF(B8=0,"",TEXT(B8,"yyyy"))
A9: =IF(E9>0,A8+1,"") | C9: =IF(B9=0,"",TEXT(B9,"mmmm")) | D9: =IF(B9=0,"",TEXT(B9,"yyyy"))
A10: =IF(E10>0,A9+1,"") | C10: =IF(B10=0,"",TEXT(B10,"mmmm")) | D10: =IF(B10=0,"",TEXT(B10,"yyyy"))
A11: =IF(E11>0,A10+1,"") | C11: =IF(B11=0,"",TEXT(B11,"mmmm")) | D11: =IF(B11=0,"",TEXT(B11,"yyyy"))
A12: =IF(E12>0,A11+1,"") | C12: =IF(B12=0,"",TEXT(B12,"mmmm")) | D12: =IF(B12=0,"",TEXT(B12,"yyyy"))
A13: =IF(E13>0,A12+1,"") | C13: =IF(B13=0,"",TEXT(B13,"mmmm")) | D13: =IF(B13=0,"",TEXT(B13,"yyyy"))
A14: =IF(E14>0,A13+1,"") | C14: =IF(B14=0,"",TEXT(B14,"mmmm")) | D14: =IF(B14=0,"",TEXT(B14,"yyyy"))
... A1348: =IF(E1348>0,A1347+1,"") | C1348: =IF(B1348=0,"",TEXT(B1348,"mmmm")) | D1348: =IF(B1348=0,"",TEXT(B1348,"yyyy"))

Sheet Other EXP
A1: Sr # | B1: Date | C1: Month | D1: Year | E1: Category | F1: Detail | G1: Quantity | H1: Amount | I1: Total Amount
A2: =IF(E2>0,1,"") -> 1 | B2: 46245 | C2: =IF(B2=0,"",TEXT(B2,"mmmm")) -> August | D2: =IF(B2=0,"",TEXT(B2,"yyyy")) -> 2026 | E2: Ads investment | F2: money for ad investment | G2: 1 | H2: 13000 | I2: =IF(G2*H2=0,"",G2*H2) -> 13000
A3: =IF(E3>0,A2+1,"") | C3: =IF(B3=0,"",TEXT(B3,"mmmm")) | D3: =IF(B3=0,"",TEXT(B3,"yyyy")) | I3: =IF(G3*H3=0,"",G3*H3)
A4: =IF(E4>0,A3+1,"") | C4: =IF(B4=0,"",TEXT(B4,"mmmm")) | D4: =IF(B4=0,"",TEXT(B4,"yyyy")) | I4: =IF(G4*H4=0,"",G4*H4)
A5: =IF(E5>0,A4+1,"") | C5: =IF(B5=0,"",TEXT(B5,"mmmm")) | D5: =IF(B5=0,"",TEXT(B5,"yyyy")) | I5: =IF(G5*H5=0,"",G5*H5)
A6: =IF(E6>0,A5+1,"") | C6: =IF(B6=0,"",TEXT(B6,"mmmm")) | D6: =IF(B6=0,"",TEXT(B6,"yyyy")) | I6: =IF(G6*H6=0,"",G6*H6)
A7: =IF(E7>0,A6+1,"") | C7: =IF(B7=0,"",TEXT(B7,"mmmm")) | D7: =IF(B7=0,"",TEXT(B7,"yyyy")) | I7: =IF(G7*H7=0,"",G7*H7)
A8: =IF(E8>0,A7+1,"") | C8: =IF(B8=0,"",TEXT(B8,"mmmm")) | D8: =IF(B8=0,"",TEXT(B8,"yyyy")) | I8: =IF(G8*H8=0,"",G8*H8)
A9: =IF(E9>0,A8+1,"") | C9: =IF(B9=0,"",TEXT(B9,"mmmm")) | D9: =IF(B9=0,"",TEXT(B9,"yyyy")) | I9: =IF(G9*H9=0,"",G9*H9)
A10: =IF(E10>0,A9+1,"") | C10: =IF(B10=0,"",TEXT(B10,"mmmm")) | D10: =IF(B10=0,"",TEXT(B10,"yyyy")) | I10: =IF(G10*H10=0,"",G10*H10)
A11: =IF(E11>0,A10+1,"") | C11: =IF(B11=0,"",TEXT(B11,"mmmm")) | D11: =IF(B11=0,"",TEXT(B11,"yyyy")) | I11: =IF(G11*H11=0,"",G11*H11)
A12: =IF(E12>0,A11+1,"") | C12: =IF(B12=0,"",TEXT(B12,"mmmm")) | D12: =IF(B12=0,"",TEXT(B12,"yyyy")) | I12: =IF(G12*H12=0,"",G12*H12)
A13: =IF(E13>0,A12+1,"") | C13: =IF(B13=0,"",TEXT(B13,"mmmm")) | D13: =IF(B13=0,"",TEXT(B13,"yyyy")) | I13: =IF(G13*H13=0,"",G13*H13)
A14: =IF(E14>0,A13+1,"") | C14: =IF(B14=0,"",TEXT(B14,"mmmm")) | D14: =IF(B14=0,"",TEXT(B14,"yyyy")) | I14: =IF(G14*H14=0,"",G14*H14)
... A1348: =IF(E1348>0,A1347+1,"") | C1348: =IF(B1348=0,"",TEXT(B1348,"mmmm")) | D1348: =IF(B1348=0,"",TEXT(B1348,"yyyy")) | I1348: =IF(G1348*H1348=0,"",G1348*H1348)

Sheet Investment
A1: Sr # | B1: Date | C1: Month | D1: Year | E1: Detail | F1: Invested amount
A2: =IF(E2>0,1,"") -> 1 | B2: 46243 | C2: =IF(B2=0,"",TEXT(B2,"mmmm")) -> August | D2: =IF(B2=0,"",TEXT(B2,"yyyy")) -> 2026 | E2: initial investment | F2: 130000
A3: =IF(E3>0,A2+1,"") -> 2 | B3: 46243 | C3: =IF(B3=0,"",TEXT(B3,"mmmm")) -> August | D3: =IF(B3=0,"",TEXT(B3,"yyyy")) -> 2026 | E3: Ad money left form previous investment | F3: 15182
A4: =IF(E4>0,A3+1,"") -> 3 | B4: 46243 | C4: =IF(B4=0,"",TEXT(B4,"mmmm")) -> August | D4: =IF(B4=0,"",TEXT(B4,"yyyy")) -> 2026 | E4: Money leftover from pervious investment | F4: 13500
A5: =IF(E5>0,A4+1,"") -> 4 | B5: 46244 | C5: =IF(B5=0,"",TEXT(B5,"mmmm")) -> August | D5: =IF(B5=0,"",TEXT(B5,"yyyy")) -> 2026 | E5: adding more investment | F5: 240000
A6: =IF(E6>0,A5+1,"") -> 5 | B6: 46245 | C6: =IF(B6=0,"",TEXT(B6,"mmmm")) -> August | D6: =IF(B6=0,"",TEXT(B6,"yyyy")) -> 2026 | E6: add to round of to the investment | F6: 1318
A7: =IF(E7>0,A6+1,"") | C7: =IF(B7=0,"",TEXT(B7,"mmmm")) | D7: =IF(B7=0,"",TEXT(B7,"yyyy"))
A8: =IF(E8>0,A7+1,"") | C8: =IF(B8=0,"",TEXT(B8,"mmmm")) | D8: =IF(B8=0,"",TEXT(B8,"yyyy"))
A9: =IF(E9>0,A8+1,"") | C9: =IF(B9=0,"",TEXT(B9,"mmmm")) | D9: =IF(B9=0,"",TEXT(B9,"yyyy"))
A10: =IF(E10>0,A9+1,"") | C10: =IF(B10=0,"",TEXT(B10,"mmmm")) | D10: =IF(B10=0,"",TEXT(B10,"yyyy"))
A11: =IF(E11>0,A10+1,"") | C11: =IF(B11=0,"",TEXT(B11,"mmmm")) | D11: =IF(B11=0,"",TEXT(B11,"yyyy"))
A12: =IF(E12>0,A11+1,"") | C12: =IF(B12=0,"",TEXT(B12,"mmmm")) | D12: =IF(B12=0,"",TEXT(B12,"yyyy"))
A13: =IF(E13>0,A12+1,"") | C13: =IF(B13=0,"",TEXT(B13,"mmmm")) | D13: =IF(B13=0,"",TEXT(B13,"yyyy"))
A14: =IF(E14>0,A13+1,"") | C14: =IF(B14=0,"",TEXT(B14,"mmmm")) | D14: =IF(B14=0,"",TEXT(B14,"yyyy"))
A15: =IF(E15>0,A14+1,"") | C15: =IF(B15=0,"",TEXT(B15,"mmmm")) | D15: =IF(B15=0,"",TEXT(B15,"yyyy"))
A16: =IF(E16>0,A15+1,"") | C16: =IF(B16=0,"",TEXT(B16,"mmmm")) | D16: =IF(B16=0,"",TEXT(B16,"yyyy"))
A17: =IF(E17>0,A16+1,"") | C17: =IF(B17=0,"",TEXT(B17,"mmmm")) | D17: =IF(B17=0,"",TEXT(B17,"yyyy"))
A18: =IF(E18>0,A17+1,"") | C18: =IF(B18=0,"",TEXT(B18,"mmmm")) | D18: =IF(B18=0,"",TEXT(B18,"yyyy"))
... A1348: =IF(E1348>0,A1347+1,"") | C1348: =IF(B1348=0,"",TEXT(B1348,"mmmm")) | D1348: =IF(B1348=0,"",TEXT(B1348,"yyyy"))

Sheet Category
A1: Category | B1: ID | D1: =IF('Product List'!C1="","",'Product List'!C1) -> Product Name | E1: =IF('Product List'!B1="","",'Product List'!B1) -> Product ID | G1: Supplier Name | H1: Payment Status | I1: Method | J1: Category | M1: Total cost | T1: Payment Method | U1: Dispatched Status | Z1: Category | AA1: Adv Rec By
A2: Tote bag | B2: TB | D2: =IF('Product List'!C2="","",'Product List'!C2) -> JW PIE Mini Hana - Light Brown | E2: =IF('Product List'!B2="","",'Product List'!B2) -> TB-001 | G2: Abdur Rehman | H2: Paid | I2: Online | J2: Ad | M2: Purchase | N2: =IF(AND(Q6="All",Q5="All"), SUM('Purchase Record'!I:I), IF(Q6="All", SUMIFS('Purchase Record'!I:I,'Purchase Record'!C:C,Q5), IF(Q5="All", SUMIFS('Purchase Record'!I:I,'Purchase Record'!D:D,Q6), SUMIFS('Purchase Record'!I:I, 'Purchase Record'!C:C,Q5, 'Purchase Record'!D:D,Q6) ))) -> 160000 | O2: Other | P2: =IF(AND(Q6="All",Q5="All"), SUMIF(SocialEXP!E:E,"<>Capital invested",SocialEXP!I:I), IF(Q6="All", SUMIFS(SocialEXP!I:I,SocialEXP!C:C,Q5,SocialEXP!E:E,"<>Capital invested"), IF(Q5="All", SUMIFS(SocialEXP!I:I,SocialEXP!D:D,Q6,SocialEXP!E:E,"<>Capital invested"), SUMIFS(SocialEXP!I:I, SocialEXP!C:C,Q5, SocialEXP!D:D,Q6,SocialEXP!E:E,"<>Capital invested") ))) -> 13000 | Q2: =IF(AND(Q6="All",Q5="All"), SUMIF(SocialEXP!E:E,"<>Capital invested",SocialEXP!I:I), IF(Q6="All", SUMIFS(SocialEXP!I:I,SocialEXP!C:C,Q5,SocialEXP!E:E,"<>Capital invested"), IF(Q5="All", SUMIFS(SocialEXP!I:I,SocialEXP!D:D,Q6,SocialEXP!E:E,"<>Capital invested"), SUMIFS(SocialEXP!I:I, SocialEXP!C:C,Q5, SocialEXP!D:D,Q6,SocialEXP!E:E,"<>Capital invested") ))) -> 13000 | T2: COD | U2: Dispatched | Z2: Ads investment | AA2: saad | AB2: Yes
A3: Top Handle | B3: TH | D3: =IF('Product List'!C3="","",'Product List'!C3) -> JW PIE Mini Hana - Black | E3: =IF('Product List'!B3="","",'Product List'!B3) -> TB-002 | G3: Fizzan | H3: Pending | I3: Cash | J3: Subscription | L3: Net Purchases | M3: =N2-O27 -> 160000 | O3: Other.EXP | P3: =IF(AND(Q6="All",Q5="All"), SUM('Other EXP'!E:E), IF(Q6="All", SUMIFS('Other EXP'!I:I,'Other EXP'!C:C,Q5), IF(Q5="All", SUMIFS('Other EXP'!I:I,'Other EXP'!D:D,Q6), SUMIFS('Other EXP'!I:I, 'Other EXP'!C:C,Q5, 'Other EXP'!D:D,Q6) ))) -> 13000 | T3: Advance | Z3: Packaging | AA3: Ali | AB3: No
A4: Shoulder Bag | B4: SB | D4: =IF('Product List'!C4="","",'Product List'!C4) -> JW PIE Elora Woven - Black | E4: =IF('Product List'!B4="","",'Product List'!B4) -> TB-003 | M4: Full Total Cost | O4: =N2+P2-O27 -> 173000 | AA4: Usama
D5: =IF('Product List'!C5="","",'Product List'!C5) -> JW PIE Elora Woven - Brown | E5: =IF('Product List'!B5="","",'Product List'!B5) -> TB-004 | M5: =N2+P3 -> 173000 | Q5: =INDEX(O$7:O$19,Q7) -> All | R5: Month
D6: =IF('Product List'!C6="","",'Product List'!C6) | E6: =IF('Product List'!B6="","",'Product List'!B6) | Q6: =INDEX(P$7:P$19,Q8) -> 2026 | R6: Year
D7: =IF('Product List'!C7="","",'Product List'!C7) | E7: =IF('Product List'!B7="","",'Product List'!B7) | L7: Sales Return | M7: Sales | N7: Net Sale | O7: All | P7: All | Q7: 1 | R7: Month | S7: Purchase | T7: Other | U7: Purchase Return | V7: Other EXP | W7: net cost | X7: Profit
D8: =IF('Product List'!C8="","",'Product List'!C8) | E8: =IF('Product List'!B8="","",'Product List'!B8) | K8: Jan | L8: =N(IF(IF($Q$6="All", SUMIFS('Sales Return'!I:I,'Sales Return'!C:C,O8), SUMIFS('Sales Return'!I:I, 'Sales Return'!C:C,O8, 'Sales Return'!D:D,$Q$6) )=0,"",IF($Q$6="All", SUMIFS('Sales Return'!I:I,'Sales Return'!C:C,O8), SUMIFS('Sales Return'!I:I, 'Sales Return'!C:C,O8, 'Sales Return'!D:D,$Q$6) ))) -> 0 | M8: =N(IF(IF($Q$6="All", SUMIFS('Sales Record'!O:O,'Sales Record'!C:C,O8), SUMIFS('Sales Record'!O:O, 'Sales Record'!C:C,O8, 'Sales Record'!D:D,$Q$6) )=0,"",(IF($Q$6="All", SUMIFS('Sales Record'!O:O,'Sales Record'!C:C,O8), SUMIFS('Sales Record'!O:O, 'Sales Record'!C:C,O8, 'Sales Record'!D:D,$Q$6) )))) -> 0 | N8: =IFERROR(IF(M8-L8=0,"",M8-L8),"") | O8: January | P8: 2026 | Q8: 2 | R8: Year | S8: =IF($Q$6="All", SUMIFS('Purchase Record'!I:I,'Purchase Record'!C:C,O8), SUMIFS('Purchase Record'!I:I, 'Purchase Record'!C:C,O8, 'Purchase Record'!D:D,$Q$6) ) -> 0 | T8: =IF($Q$6="All", SUMIFS(SocialEXP!I:I,SocialEXP!C:C,O8,SocialEXP!E:E,"<>Capital invested"), SUMIFS(SocialEXP!I:I, SocialEXP!C:C,O8,SocialEXP!E:E,"<>Capital invested", SocialEXP!D:D,$Q$6)) -> 0 | U8: =IF($Q$6="All", SUMIFS('Purchase Return'!I:I,'Purchase Return'!C:C,O8), SUMIFS('Purchase Return'!I:I, 'Purchase Return'!C:C,O8, 'Purchase Return'!D:D,$Q$6)) -> 0 | V8: =IF($Q$6="All", SUMIFS('Other EXP'!I:I,'Other EXP'!C:C,O8), SUMIFS('Other EXP'!I:I, 'Other EXP'!C:C,O8, 'Other EXP'!D:D,$Q$6)) -> 0 | W8: =IF(S8+V8-U8=0,"",S8+V8-U8) | X8: =IF(N(N8)-N(W8)=0,"",N(N8)-N(W8))
D9: =IF('Product List'!C9="","",'Product List'!C9) | E9: =IF('Product List'!B9="","",'Product List'!B9) | K9: Feb | L9: =N(IF(IF($Q$6="All", SUMIFS('Sales Return'!I:I,'Sales Return'!C:C,O9), SUMIFS('Sales Return'!I:I, 'Sales Return'!C:C,O9, 'Sales Return'!D:D,$Q$6) )=0,"",IF($Q$6="All", SUMIFS('Sales Return'!I:I,'Sales Return'!C:C,O9), SUMIFS('Sales Return'!I:I, 'Sales Return'!C:C,O9, 'Sales Return'!D:D,$Q$6) ))) -> 0 | M9: =N(IF(IF($Q$6="All", SUMIFS('Sales Record'!O:O,'Sales Record'!C:C,O9), SUMIFS('Sales Record'!O:O, 'Sales Record'!C:C,O9, 'Sales Record'!D:D,$Q$6) )=0,"",(IF($Q$6="All", SUMIFS('Sales Record'!O:O,'Sales Record'!C:C,O9), SUMIFS('Sales Record'!O:O, 'Sales Record'!C:C,O9, 'Sales Record'!D:D,$Q$6) )))) -> 0 | N9: =IFERROR(IF(M9-L9=0,"",M9-L9),"") | O9: February | P9: 2027 | Q9: Ads Capital invested | S9: =IF($Q$6="All", SUMIFS('Purchase Record'!I:I,'Purchase Record'!C:C,O9), SUMIFS('Purchase Record'!I:I, 'Purchase Record'!C:C,O9, 'Purchase Record'!D:D,$Q$6) ) -> 0 | T9: =IF($Q$6="All", SUMIFS(SocialEXP!I:I,SocialEXP!C:C,O9,SocialEXP!E:E,"<>Capital invested"), SUMIFS(SocialEXP!I:I, SocialEXP!C:C,O9,SocialEXP!E:E,"<>Capital invested", SocialEXP!D:D,$Q$6)) -> 0 | U9: =IF($Q$6="All", SUMIFS('Purchase Return'!I:I,'Purchase Return'!C:C,O9), SUMIFS('Purchase Return'!I:I, 'Purchase Return'!C:C,O9, 'Purchase Return'!D:D,$Q$6)) -> 0 | V9: =IF($Q$6="All", SUMIFS('Other EXP'!I:I,'Other EXP'!C:C,O9), SUMIFS('Other EXP'!I:I, 'Other EXP'!C:C,O9, 'Other EXP'!D:D,$Q$6)) -> 0 | W9: =IF(S9+V9-U9=0,"",S9+V9-U9) | X9: =IF(N(N9)-N(W9)=0,"",N(N9)-N(W9))
D10: =IF('Product List'!C10="","",'Product List'!C10) | E10: =IF('Product List'!B10="","",'Product List'!B10) | K10: Mar | L10: =N(IF(IF($Q$6="All", SUMIFS('Sales Return'!I:I,'Sales Return'!C:C,O10), SUMIFS('Sales Return'!I:I, 'Sales Return'!C:C,O10, 'Sales Return'!D:D,$Q$6) )=0,"",IF($Q$6="All", SUMIFS('Sales Return'!I:I,'Sales Return'!C:C,O10), SUMIFS('Sales Return'!I:I, 'Sales Return'!C:C,O10, 'Sales Return'!D:D,$Q$6) ))) -> 0 | M10: =N(IF(IF($Q$6="All", SUMIFS('Sales Record'!O:O,'Sales Record'!C:C,O10), SUMIFS('Sales Record'!O:O, 'Sales Record'!C:C,O10, 'Sales Record'!D:D,$Q$6) )=0,"",(IF($Q$6="All", SUMIFS('Sales Record'!O:O,'Sales Record'!C:C,O10), SUMIFS('Sales Record'!O:O, 'Sales Record'!C:C,O10, 'Sales Record'!D:D,$Q$6) )))) -> 0 | N10: =IFERROR(IF(M10-L10=0,"",M10-L10),"") | O10: March | P10: 2028 | Q10: =(IF(AND(Q6="All",Q5="All"), SUM('Ads investment'!F:F), IF(Q6="All", SUMIFS('Ads investment'!F:F,'Ads investment'!C:C,Q5), IF(Q5="All", SUMIFS('Ads investment'!F:F,'Ads investment'!D:D,Q6), SUMIFS('Ads investment'!F:F, 'Ads investment'!C:C,Q5, 'Ads investment'!D:D,Q6) )))) -> 13000 | S10: =IF($Q$6="All", SUMIFS('Purchase Record'!I:I,'Purchase Record'!C:C,O10), SUMIFS('Purchase Record'!I:I, 'Purchase Record'!C:C,O10, 'Purchase Record'!D:D,$Q$6) ) -> 0 | T10: =IF($Q$6="All", SUMIFS(SocialEXP!I:I,SocialEXP!C:C,O10,SocialEXP!E:E,"<>Capital invested"), SUMIFS(SocialEXP!I:I, SocialEXP!C:C,O10,SocialEXP!E:E,"<>Capital invested", SocialEXP!D:D,$Q$6)) -> 0 | U10: =IF($Q$6="All", SUMIFS('Purchase Return'!I:I,'Purchase Return'!C:C,O10), SUMIFS('Purchase Return'!I:I, 'Purchase Return'!C:C,O10, 'Purchase Return'!D:D,$Q$6)) -> 0 | V10: =IF($Q$6="All", SUMIFS('Other EXP'!I:I,'Other EXP'!C:C,O10), SUMIFS('Other EXP'!I:I, 'Other EXP'!C:C,O10, 'Other EXP'!D:D,$Q$6)) -> 0 | W10: =IF(S10+V10-U10=0,"",S10+V10-U10) | X10: =IF(N(N10)-N(W10)=0,"",N(N10)-N(W10))
D11: =IF('Product List'!C11="","",'Product List'!C11) | E11: =IF('Product List'!B11="","",'Product List'!B11) | K11: Apr | L11: =N(IF(IF($Q$6="All", SUMIFS('Sales Return'!I:I,'Sales Return'!C:C,O11), SUMIFS('Sales Return'!I:I, 'Sales Return'!C:C,O11, 'Sales Return'!D:D,$Q$6) )=0,"",IF($Q$6="All", SUMIFS('Sales Return'!I:I,'Sales Return'!C:C,O11), SUMIFS('Sales Return'!I:I, 'Sales Return'!C:C,O11, 'Sales Return'!D:D,$Q$6) ))) -> 0 | M11: =N(IF(IF($Q$6="All", SUMIFS('Sales Record'!O:O,'Sales Record'!C:C,O11), SUMIFS('Sales Record'!O:O, 'Sales Record'!C:C,O11, 'Sales Record'!D:D,$Q$6) )=0,"",(IF($Q$6="All", SUMIFS('Sales Record'!O:O,'Sales Record'!C:C,O11), SUMIFS('Sales Record'!O:O, 'Sales Record'!C:C,O11, 'Sales Record'!D:D,$Q$6) )))) -> 0 | N11: =IFERROR(IF(M11-L11=0,"",M11-L11),"") | O11: April | P11: 2029 | S11: =IF($Q$6="All", SUMIFS('Purchase Record'!I:I,'Purchase Record'!C:C,O11), SUMIFS('Purchase Record'!I:I, 'Purchase Record'!C:C,O11, 'Purchase Record'!D:D,$Q$6) ) -> 160000 | T11: =IF($Q$6="All", SUMIFS(SocialEXP!I:I,SocialEXP!C:C,O11,SocialEXP!E:E,"<>Capital invested"), SUMIFS(SocialEXP!I:I, SocialEXP!C:C,O11,SocialEXP!E:E,"<>Capital invested", SocialEXP!D:D,$Q$6)) -> 0 | U11: =IF($Q$6="All", SUMIFS('Purchase Return'!I:I,'Purchase Return'!C:C,O11), SUMIFS('Purchase Return'!I:I, 'Purchase Return'!C:C,O11, 'Purchase Return'!D:D,$Q$6)) -> 0 | V11: =IF($Q$6="All", SUMIFS('Other EXP'!I:I,'Other EXP'!C:C,O11), SUMIFS('Other EXP'!I:I, 'Other EXP'!C:C,O11, 'Other EXP'!D:D,$Q$6)) -> 0 | W11: =IF(S11+V11-U11=0,"",S11+V11-U11) -> 160000 | X11: =IF(N(N11)-N(W11)=0,"",N(N11)-N(W11)) -> -160000
D12: =IF('Product List'!C12="","",'Product List'!C12) | E12: =IF('Product List'!B12="","",'Product List'!B12) | K12: May | L12: =N(IF(IF($Q$6="All", SUMIFS('Sales Return'!I:I,'Sales Return'!C:C,O12), SUMIFS('Sales Return'!I:I, 'Sales Return'!C:C,O12, 'Sales Return'!D:D,$Q$6) )=0,"",IF($Q$6="All", SUMIFS('Sales Return'!I:I,'Sales Return'!C:C,O12), SUMIFS('Sales Return'!I:I, 'Sales Return'!C:C,O12, 'Sales Return'!D:D,$Q$6) ))) -> 0 | M12: =N(IF(IF($Q$6="All", SUMIFS('Sales Record'!O:O,'Sales Record'!C:C,O12), SUMIFS('Sales Record'!O:O, 'Sales Record'!C:C,O12, 'Sales Record'!D:D,$Q$6) )=0,"",(IF($Q$6="All", SUMIFS('Sales Record'!O:O,'Sales Record'!C:C,O12), SUMIFS('Sales Record'!O:O, 'Sales Record'!C:C,O12, 'Sales Record'!D:D,$Q$6) )))) -> 0 | N12: =IFERROR(IF(M12-L12=0,"",M12-L12),"") | O12: May | P12: 2030 | Q12: =SUMIF(SocialEXP!E:E,"<>Capital invested",SocialEXP!I:I) -> 13000 | R12: =Q10-Q12 -> 0 | S12: =IF($Q$6="All", SUMIFS('Purchase Record'!I:I,'Purchase Record'!C:C,O12), SUMIFS('Purchase Record'!I:I, 'Purchase Record'!C:C,O12, 'Purchase Record'!D:D,$Q$6) ) -> 0 | T12: =IF($Q$6="All", SUMIFS(SocialEXP!I:I,SocialEXP!C:C,O12,SocialEXP!E:E,"<>Capital invested"), SUMIFS(SocialEXP!I:I, SocialEXP!C:C,O12,SocialEXP!E:E,"<>Capital invested", SocialEXP!D:D,$Q$6)) -> 0 | U12: =IF($Q$6="All", SUMIFS('Purchase Return'!I:I,'Purchase Return'!C:C,O12), SUMIFS('Purchase Return'!I:I, 'Purchase Return'!C:C,O12, 'Purchase Return'!D:D,$Q$6)) -> 0 | V12: =IF($Q$6="All", SUMIFS('Other EXP'!I:I,'Other EXP'!C:C,O12), SUMIFS('Other EXP'!I:I, 'Other EXP'!C:C,O12, 'Other EXP'!D:D,$Q$6)) -> 0 | W12: =IF(S12+V12-U12=0,"",S12+V12-U12) | X12: =IF(N(N12)-N(W12)=0,"",N(N12)-N(W12))
D13: =IF('Product List'!C13="","",'Product List'!C13) | E13: =IF('Product List'!B13="","",'Product List'!B13) | K13: Jun | L13: =N(IF(IF($Q$6="All", SUMIFS('Sales Return'!I:I,'Sales Return'!C:C,O13), SUMIFS('Sales Return'!I:I, 'Sales Return'!C:C,O13, 'Sales Return'!D:D,$Q$6) )=0,"",IF($Q$6="All", SUMIFS('Sales Return'!I:I,'Sales Return'!C:C,O13), SUMIFS('Sales Return'!I:I, 'Sales Return'!C:C,O13, 'Sales Return'!D:D,$Q$6) ))) -> 0 | M13: =N(IF(IF($Q$6="All", SUMIFS('Sales Record'!O:O,'Sales Record'!C:C,O13), SUMIFS('Sales Record'!O:O, 'Sales Record'!C:C,O13, 'Sales Record'!D:D,$Q$6) )=0,"",(IF($Q$6="All", SUMIFS('Sales Record'!O:O,'Sales Record'!C:C,O13), SUMIFS('Sales Record'!O:O, 'Sales Record'!C:C,O13, 'Sales Record'!D:D,$Q$6) )))) -> 0 | N13: =IFERROR(IF(M13-L13=0,"",M13-L13),"") | O13: June | P13: 2031 | S13: =IF($Q$6="All", SUMIFS('Purchase Record'!I:I,'Purchase Record'!C:C,O13), SUMIFS('Purchase Record'!I:I, 'Purchase Record'!C:C,O13, 'Purchase Record'!D:D,$Q$6) ) -> 0 | T13: =IF($Q$6="All", SUMIFS(SocialEXP!I:I,SocialEXP!C:C,O13,SocialEXP!E:E,"<>Capital invested"), SUMIFS(SocialEXP!I:I, SocialEXP!C:C,O13,SocialEXP!E:E,"<>Capital invested", SocialEXP!D:D,$Q$6)) -> 0 | U13: =IF($Q$6="All", SUMIFS('Purchase Return'!I:I,'Purchase Return'!C:C,O13), SUMIFS('Purchase Return'!I:I, 'Purchase Return'!C:C,O13, 'Purchase Return'!D:D,$Q$6)) -> 0 | V13: =IF($Q$6="All", SUMIFS('Other EXP'!I:I,'Other EXP'!C:C,O13), SUMIFS('Other EXP'!I:I, 'Other EXP'!C:C,O13, 'Other EXP'!D:D,$Q$6)) -> 0 | W13: =IF(S13+V13-U13=0,"",S13+V13-U13) | X13: =IF(N(N13)-N(W13)=0,"",N(N13)-N(W13))
D14: =IF('Product List'!C14="","",'Product List'!C14) | E14: =IF('Product List'!B14="","",'Product List'!B14) | K14: Jul | L14: =N(IF(IF($Q$6="All", SUMIFS('Sales Return'!I:I,'Sales Return'!C:C,O14), SUMIFS('Sales Return'!I:I, 'Sales Return'!C:C,O14, 'Sales Return'!D:D,$Q$6) )=0,"",IF($Q$6="All", SUMIFS('Sales Return'!I:I,'Sales Return'!C:C,O14), SUMIFS('Sales Return'!I:I, 'Sales Return'!C:C,O14, 'Sales Return'!D:D,$Q$6) ))) -> 0 | M14: =N(IF(IF($Q$6="All", SUMIFS('Sales Record'!O:O,'Sales Record'!C:C,O14), SUMIFS('Sales Record'!O:O, 'Sales Record'!C:C,O14, 'Sales Record'!D:D,$Q$6) )=0,"",(IF($Q$6="All", SUMIFS('Sales Record'!O:O,'Sales Record'!C:C,O14), SUMIFS('Sales Record'!O:O, 'Sales Record'!C:C,O14, 'Sales Record'!D:D,$Q$6) )))) -> 0 | N14: =IFERROR(IF(M14-L14=0,"",M14-L14),"") | O14: July | P14: 2032 | Q14: Ads Capital invested | S14: =IF($Q$6="All", SUMIFS('Purchase Record'!I:I,'Purchase Record'!C:C,O14), SUMIFS('Purchase Record'!I:I, 'Purchase Record'!C:C,O14, 'Purchase Record'!D:D,$Q$6) ) -> 0 | T14: =IF($Q$6="All", SUMIFS(SocialEXP!I:I,SocialEXP!C:C,O14,SocialEXP!E:E,"<>Capital invested"), SUMIFS(SocialEXP!I:I, SocialEXP!C:C,O14,SocialEXP!E:E,"<>Capital invested", SocialEXP!D:D,$Q$6)) -> 0 | U14: =IF($Q$6="All", SUMIFS('Purchase Return'!I:I,'Purchase Return'!C:C,O14), SUMIFS('Purchase Return'!I:I, 'Purchase Return'!C:C,O14, 'Purchase Return'!D:D,$Q$6)) -> 0 | V14: =IF($Q$6="All", SUMIFS('Other EXP'!I:I,'Other EXP'!C:C,O14), SUMIFS('Other EXP'!I:I, 'Other EXP'!C:C,O14, 'Other EXP'!D:D,$Q$6)) -> 0 | W14: =IF(S14+V14-U14=0,"",S14+V14-U14) | X14: =IF(N(N14)-N(W14)=0,"",N(N14)-N(W14))
D15: =IF('Product List'!C15="","",'Product List'!C15) | E15: =IF('Product List'!B15="","",'Product List'!B15) | K15: Aug | L15: =N(IF(IF($Q$6="All", SUMIFS('Sales Return'!I:I,'Sales Return'!C:C,O15), SUMIFS('Sales Return'!I:I, 'Sales Return'!C:C,O15, 'Sales Return'!D:D,$Q$6) )=0,"",IF($Q$6="All", SUMIFS('Sales Return'!I:I,'Sales Return'!C:C,O15), SUMIFS('Sales Return'!I:I, 'Sales Return'!C:C,O15, 'Sales Return'!D:D,$Q$6) ))) -> 0 | M15: =N(IF(IF($Q$6="All", SUMIFS('Sales Record'!O:O,'Sales Record'!C:C,O15), SUMIFS('Sales Record'!O:O, 'Sales Record'!C:C,O15, 'Sales Record'!D:D,$Q$6) )=0,"",(IF($Q$6="All", SUMIFS('Sales Record'!O:O,'Sales Record'!C:C,O15), SUMIFS('Sales Record'!O:O, 'Sales Record'!C:C,O15, 'Sales Record'!D:D,$Q$6) )))) -> 220000 | N15: =IFERROR(IF(M15-L15=0,"",M15-L15),"") -> 220000 | O15: August | P15: 2033 | Q15: =(IF(AND(Q6="All",Q5="All"), SUM(Investment!F:F), IF(Q6="All", SUMIFS(Investment!F:F,Investment!C:C,Q5), IF(Q5="All", SUMIFS(Investment!F:F,Investment!D:D,Q6), SUMIFS(Investment!F:F, Investment!C:C,Q5, Investment!D:D,Q6) )))) -> 400000 | S15: =IF($Q$6="All", SUMIFS('Purchase Record'!I:I,'Purchase Record'!C:C,O15), SUMIFS('Purchase Record'!I:I, 'Purchase Record'!C:C,O15, 'Purchase Record'!D:D,$Q$6) ) -> 0 | T15: =IF($Q$6="All", SUMIFS(SocialEXP!I:I,SocialEXP!C:C,O15,SocialEXP!E:E,"<>Capital invested"), SUMIFS(SocialEXP!I:I, SocialEXP!C:C,O15,SocialEXP!E:E,"<>Capital invested", SocialEXP!D:D,$Q$6)) -> 13000 | U15: =IF($Q$6="All", SUMIFS('Purchase Return'!I:I,'Purchase Return'!C:C,O15), SUMIFS('Purchase Return'!I:I, 'Purchase Return'!C:C,O15, 'Purchase Return'!D:D,$Q$6)) -> 0 | V15: =IF($Q$6="All", SUMIFS('Other EXP'!I:I,'Other EXP'!C:C,O15), SUMIFS('Other EXP'!I:I, 'Other EXP'!C:C,O15, 'Other EXP'!D:D,$Q$6)) -> 13000 | W15: =IF(S15+V15-U15=0,"",S15+V15-U15) -> 13000 | X15: =IF(N(N15)-N(W15)=0,"",N(N15)-N(W15)) -> 207000
D16: =IF('Product List'!C16="","",'Product List'!C16) | E16: =IF('Product List'!B16="","",'Product List'!B16) | K16: Sep | L16: =N(IF(IF($Q$6="All", SUMIFS('Sales Return'!I:I,'Sales Return'!C:C,O16), SUMIFS('Sales Return'!I:I, 'Sales Return'!C:C,O16, 'Sales Return'!D:D,$Q$6) )=0,"",IF($Q$6="All", SUMIFS('Sales Return'!I:I,'Sales Return'!C:C,O16), SUMIFS('Sales Return'!I:I, 'Sales Return'!C:C,O16, 'Sales Return'!D:D,$Q$6) ))) -> 0 | M16: =N(IF(IF($Q$6="All", SUMIFS('Sales Record'!O:O,'Sales Record'!C:C,O16), SUMIFS('Sales Record'!O:O, 'Sales Record'!C:C,O16, 'Sales Record'!D:D,$Q$6) )=0,"",(IF($Q$6="All", SUMIFS('Sales Record'!O:O,'Sales Record'!C:C,O16), SUMIFS('Sales Record'!O:O, 'Sales Record'!C:C,O16, 'Sales Record'!D:D,$Q$6) )))) -> 0 | N16: =IFERROR(IF(M16-L16=0,"",M16-L16),"") | O16: September | P16: 2034 | S16: =IF($Q$6="All", SUMIFS('Purchase Record'!I:I,'Purchase Record'!C:C,O16), SUMIFS('Purchase Record'!I:I, 'Purchase Record'!C:C,O16, 'Purchase Record'!D:D,$Q$6) ) -> 0 | T16: =IF($Q$6="All", SUMIFS(SocialEXP!I:I,SocialEXP!C:C,O16,SocialEXP!E:E,"<>Capital invested"), SUMIFS(SocialEXP!I:I, SocialEXP!C:C,O16,SocialEXP!E:E,"<>Capital invested", SocialEXP!D:D,$Q$6)) -> 0 | U16: =IF($Q$6="All", SUMIFS('Purchase Return'!I:I,'Purchase Return'!C:C,O16), SUMIFS('Purchase Return'!I:I, 'Purchase Return'!C:C,O16, 'Purchase Return'!D:D,$Q$6)) -> 0 | V16: =IF($Q$6="All", SUMIFS('Other EXP'!I:I,'Other EXP'!C:C,O16), SUMIFS('Other EXP'!I:I, 'Other EXP'!C:C,O16, 'Other EXP'!D:D,$Q$6)) -> 0 | W16: =IF(S16+V16-U16=0,"",S16+V16-U16) | X16: =IF(N(N16)-N(W16)=0,"",N(N16)-N(W16))
D17: =IF('Product List'!C17="","",'Product List'!C17) | E17: =IF('Product List'!B17="","",'Product List'!B17) | K17: Oct | L17: =N(IF(IF($Q$6="All", SUMIFS('Sales Return'!I:I,'Sales Return'!C:C,O17), SUMIFS('Sales Return'!I:I, 'Sales Return'!C:C,O17, 'Sales Return'!D:D,$Q$6) )=0,"",IF($Q$6="All", SUMIFS('Sales Return'!I:I,'Sales Return'!C:C,O17), SUMIFS('Sales Return'!I:I, 'Sales Return'!C:C,O17, 'Sales Return'!D:D,$Q$6) ))) -> 0 | M17: =N(IF(IF($Q$6="All", SUMIFS('Sales Record'!O:O,'Sales Record'!C:C,O17), SUMIFS('Sales Record'!O:O, 'Sales Record'!C:C,O17, 'Sales Record'!D:D,$Q$6) )=0,"",(IF($Q$6="All", SUMIFS('Sales Record'!O:O,'Sales Record'!C:C,O17), SUMIFS('Sales Record'!O:O, 'Sales Record'!C:C,O17, 'Sales Record'!D:D,$Q$6) )))) -> 0 | N17: =IFERROR(IF(M17-L17=0,"",M17-L17),"") | O17: October | P17: 2035 | S17: =IF($Q$6="All", SUMIFS('Purchase Record'!I:I,'Purchase Record'!C:C,O17), SUMIFS('Purchase Record'!I:I, 'Purchase Record'!C:C,O17, 'Purchase Record'!D:D,$Q$6) ) -> 0 | T17: =IF($Q$6="All", SUMIFS(SocialEXP!I:I,SocialEXP!C:C,O17,SocialEXP!E:E,"<>Capital invested"), SUMIFS(SocialEXP!I:I, SocialEXP!C:C,O17,SocialEXP!E:E,"<>Capital invested", SocialEXP!D:D,$Q$6)) -> 0 | U17: =IF($Q$6="All", SUMIFS('Purchase Return'!I:I,'Purchase Return'!C:C,O17), SUMIFS('Purchase Return'!I:I, 'Purchase Return'!C:C,O17, 'Purchase Return'!D:D,$Q$6)) -> 0 | V17: =IF($Q$6="All", SUMIFS('Other EXP'!I:I,'Other EXP'!C:C,O17), SUMIFS('Other EXP'!I:I, 'Other EXP'!C:C,O17, 'Other EXP'!D:D,$Q$6)) -> 0 | W17: =IF(S17+V17-U17=0,"",S17+V17-U17) | X17: =IF(N(N17)-N(W17)=0,"",N(N17)-N(W17))
D18: =IF('Product List'!C18="","",'Product List'!C18) | E18: =IF('Product List'!B18="","",'Product List'!B18) | K18: Nov | L18: =N(IF(IF($Q$6="All", SUMIFS('Sales Return'!I:I,'Sales Return'!C:C,O18), SUMIFS('Sales Return'!I:I, 'Sales Return'!C:C,O18, 'Sales Return'!D:D,$Q$6) )=0,"",IF($Q$6="All", SUMIFS('Sales Return'!I:I,'Sales Return'!C:C,O18), SUMIFS('Sales Return'!I:I, 'Sales Return'!C:C,O18, 'Sales Return'!D:D,$Q$6) ))) -> 0 | M18: =N(IF(IF($Q$6="All", SUMIFS('Sales Record'!O:O,'Sales Record'!C:C,O18), SUMIFS('Sales Record'!O:O, 'Sales Record'!C:C,O18, 'Sales Record'!D:D,$Q$6) )=0,"",(IF($Q$6="All", SUMIFS('Sales Record'!O:O,'Sales Record'!C:C,O18), SUMIFS('Sales Record'!O:O, 'Sales Record'!C:C,O18, 'Sales Record'!D:D,$Q$6) )))) -> 0 | N18: =IFERROR(IF(M18-L18=0,"",M18-L18),"") | O18: November | P18: 2036 | S18: =IF($Q$6="All", SUMIFS('Purchase Record'!I:I,'Purchase Record'!C:C,O18), SUMIFS('Purchase Record'!I:I, 'Purchase Record'!C:C,O18, 'Purchase Record'!D:D,$Q$6) ) -> 0 | T18: =IF($Q$6="All", SUMIFS(SocialEXP!I:I,SocialEXP!C:C,O18,SocialEXP!E:E,"<>Capital invested"), SUMIFS(SocialEXP!I:I, SocialEXP!C:C,O18,SocialEXP!E:E,"<>Capital invested", SocialEXP!D:D,$Q$6)) -> 0 | U18: =IF($Q$6="All", SUMIFS('Purchase Return'!I:I,'Purchase Return'!C:C,O18), SUMIFS('Purchase Return'!I:I, 'Purchase Return'!C:C,O18, 'Purchase Return'!D:D,$Q$6)) -> 0 | V18: =IF($Q$6="All", SUMIFS('Other EXP'!I:I,'Other EXP'!C:C,O18), SUMIFS('Other EXP'!I:I, 'Other EXP'!C:C,O18, 'Other EXP'!D:D,$Q$6)) -> 0 | W18: =IF(S18+V18-U18=0,"",S18+V18-U18) | X18: =IF(N(N18)-N(W18)=0,"",N(N18)-N(W18))
D19: =IF('Product List'!C19="","",'Product List'!C19) | E19: =IF('Product List'!B19="","",'Product List'!B19) | K19: Dec | L19: =N(IF(IF($Q$6="All", SUMIFS('Sales Return'!I:I,'Sales Return'!C:C,O19), SUMIFS('Sales Return'!I:I, 'Sales Return'!C:C,O19, 'Sales Return'!D:D,$Q$6) )=0,"",IF($Q$6="All", SUMIFS('Sales Return'!I:I,'Sales Return'!C:C,O19), SUMIFS('Sales Return'!I:I, 'Sales Return'!C:C,O19, 'Sales Return'!D:D,$Q$6) ))) -> 0 | M19: =N(IF(IF($Q$6="All", SUMIFS('Sales Record'!O:O,'Sales Record'!C:C,O19), SUMIFS('Sales Record'!O:O, 'Sales Record'!C:C,O19, 'Sales Record'!D:D,$Q$6) )=0,"",(IF($Q$6="All", SUMIFS('Sales Record'!O:O,'Sales Record'!C:C,O19), SUMIFS('Sales Record'!O:O, 'Sales Record'!C:C,O19, 'Sales Record'!D:D,$Q$6) )))) -> 0 | N19: =IFERROR(IF(M19-L19=0,"",M19-L19),"") | O19: December | P19: 2037 | S19: =IF($Q$6="All", SUMIFS('Purchase Record'!I:I,'Purchase Record'!C:C,O19), SUMIFS('Purchase Record'!I:I, 'Purchase Record'!C:C,O19, 'Purchase Record'!D:D,$Q$6) ) -> 0 | T19: =IF($Q$6="All", SUMIFS(SocialEXP!I:I,SocialEXP!C:C,O19,SocialEXP!E:E,"<>Capital invested"), SUMIFS(SocialEXP!I:I, SocialEXP!C:C,O19,SocialEXP!E:E,"<>Capital invested", SocialEXP!D:D,$Q$6)) -> 0 | U19: =IF($Q$6="All", SUMIFS('Purchase Return'!I:I,'Purchase Return'!C:C,O19), SUMIFS('Purchase Return'!I:I, 'Purchase Return'!C:C,O19, 'Purchase Return'!D:D,$Q$6)) -> 0 | V19: =IF($Q$6="All", SUMIFS('Other EXP'!I:I,'Other EXP'!C:C,O19), SUMIFS('Other EXP'!I:I, 'Other EXP'!C:C,O19, 'Other EXP'!D:D,$Q$6)) -> 0 | W19: =IF(S19+V19-U19=0,"",S19+V19-U19) | X19: =IF(N(N19)-N(W19)=0,"",N(N19)-N(W19))
D20: =IF('Product List'!C20="","",'Product List'!C20) | E20: =IF('Product List'!B20="","",'Product List'!B20) | T20: max | V20: max
D21: =IF('Product List'!C21="","",'Product List'!C21) | E21: =IF('Product List'!B21="","",'Product List'!B21) | M21: Total Revenue | Q21: =O22-O25 -> 215000 | T21: =MAX(T8:T19) -> 13000 | V21: =MAX(V8:V19) -> 13000
D22: =IF('Product List'!C22="","",'Product List'!C22) | E22: =IF('Product List'!B22="","",'Product List'!B22) | N22: Sale | O22: =IF(AND(Q6="All",Q5="All"), SUMIFS('Sales Record'!O:O,'Sales Record'!R:R,"Paid")+ SUMIFS('Sales Record'!J:J,'Sales Record'!R:R,"<>Paid"), IF(Q6="All", SUMIFS('Sales Record'!O:O,'Sales Record'!C:C,Q5,'Sales Record'!R:R,"Paid")+ SUMIFS('Sales Record'!J:J,'Sales Record'!C:C,Q5,'Sales Record'!R:R,"<>Paid"), IF(Q5="All", SUMIFS('Sales Record'!O:O,'Sales Record'!D:D,Q6,'Sales Record'!R:R,"Paid")+ SUMIFS('Sales Record'!J:J,'Sales Record'!D:D,Q6,'Sales Record'!R:R,"<>Paid"), SUMIFS('Sales Record'!O:O,'Sales Record'!C:C,Q5,'Sales Record'!D:D,Q6,'Sales Record'!R:R,"Paid")+ SUMIFS('Sales Record'!J:J,'Sales Record'!C:C,Q5,'Sales Record'!D:D,Q6,'Sales Record'!R:R,"<>Paid") ))) -> 215000 | T22: =MATCH(T21,T8:T19,0) -> 8 | V22: =MATCH(V21,V8:V19,0) -> 8
D23: =IF('Product List'!C23="","",'Product List'!C23) | E23: =IF('Product List'!B23="","",'Product List'!B23) | T23: =INDEX(O8:O19,T22) -> August | V23: =INDEX(O8:O19,V22) -> August
D24: =IF('Product List'!C24="","",'Product List'!C24) | E24: =IF('Product List'!B24="","",'Product List'!B24) | M24: Sales Return
D25: =IF('Product List'!C25="","",'Product List'!C25) | E25: =IF('Product List'!B25="","",'Product List'!B25) | M25: Returned Amount | O25: =IF(AND(Q6="All",Q5="All"), SUM('Sales Return'!I:I), IF(Q6="All", SUMIFS('Sales Return'!I:I,'Sales Return'!C:C,Q5), IF(Q5="All", SUMIFS('Sales Return'!I:I,'Sales Return'!D:D,Q6), SUMIFS('Sales Return'!I:I, 'Sales Return'!C:C,Q5, 'Sales Return'!D:D,Q6) ))) -> 0
D26: =IF('Product List'!C26="","",'Product List'!C26) | E26: =IF('Product List'!B26="","",'Product List'!B26) | M26: Purchase Return
D27: =IF('Product List'!C27="","",'Product List'!C27) | E27: =IF('Product List'!B27="","",'Product List'!B27) | M27: Returned Cost | O27: =IF(AND(Q6="All",Q5="All"), SUM('Purchase Return'!I:I), IF(Q6="All", SUMIFS('Purchase Return'!I:I,'Purchase Return'!C:C,Q5), IF(Q5="All", SUMIFS('Purchase Return'!I:I,'Purchase Return'!D:D,Q6), SUMIFS('Purchase Return'!I:I, 'Purchase Return'!C:C,Q5, 'Purchase Return'!D:D,Q6) ))) -> 0
D28: =IF('Product List'!C28="","",'Product List'!C28) | E28: =IF('Product List'!B28="","",'Product List'!B28)
D29: =IF('Product List'!C29="","",'Product List'!C29) | E29: =IF('Product List'!B29="","",'Product List'!B29) | N29: =M30 -> Profit | O29: =L3 -> Net Purchases | P29: Ad Expenses | Q29: Total sales | R29: other Exp
D30: =IF('Product List'!C30="","",'Product List'!C30) | E30: =IF('Product List'!B30="","",'Product List'!B30) | M30: Profit | N30: =O22+O27-O25-M5 -> 42000 | O30: =M3 -> 160000 | P30: =P2 -> 13000 | Q30: =Q21 -> 215000 | R30: =P3 -> 13000 | S30: =Q30-O30 -> 55000
D31: =IF('Product List'!C31="","",'Product List'!C31) | E31: =IF('Product List'!B31="","",'Product List'!B31) | M31: Profit Margin' | N31: =IFERROR(IF(IF(Q21=0,"-",N30/Q21)<0,"-",IF(Q21=0,"-",N30/Q21)),"-") -> 0.19534884
D32: =IF('Product List'!C32="","",'Product List'!C32) | E32: =IF('Product List'!B32="","",'Product List'!B32) | M32: Cash in hand | N32: =O22+O27-O25-M5+Q15 -> 442000
D33: =IF('Product List'!C33="","",'Product List'!C33) | E33: =IF('Product List'!B33="","",'Product List'!B33)
D34: =IF('Product List'!C34="","",'Product List'!C34) | E34: =IF('Product List'!B34="","",'Product List'!B34)
D35: =IF('Product List'!C35="","",'Product List'!C35) | E35: =IF('Product List'!B35="","",'Product List'!B35)
D36: =IF('Product List'!C36="","",'Product List'!C36) | E36: =IF('Product List'!B36="","",'Product List'!B36)
D37: =IF('Product List'!C37="","",'Product List'!C37) | E37: =IF('Product List'!B37="","",'Product List'!B37)
D38: =IF('Product List'!C38="","",'Product List'!C38) | E38: =IF('Product List'!B38="","",'Product List'!B38)
D39: =IF('Product List'!C39="","",'Product List'!C39) | E39: =IF('Product List'!B39="","",'Product List'!B39)
D40: =IF('Product List'!C40="","",'Product List'!C40) | E40: =IF('Product List'!B40="","",'Product List'!B40)
...

Sheet Sheet4
A1: =IF('Product List'!B1="","",'Product List'!B1) -> Product ID | B1: =IF('Product List'!C1="","",'Product List'!C1) -> Product Name | C1: Total purchased | D1: Total sold | E1: Total Sales returned | F1: Total Purchases Return | G1: Current
A2: =IF('Product List'!B2="","",'Product List'!B2) -> TB-001 | B2: =IF('Product List'!C2="","",'Product List'!C2) -> JW PIE Mini Hana - Light Brown | C2: =IF(SUMIFS('Purchase Record'!G:G,'Purchase Record'!F:F,Sheet4!A2)=0,"",SUMIFS('Purchase Record'!G:G,'Purchase Record'!F:F,Sheet4!A2)) -> 1 | D2: =IF(SUMIFS('Sales Record'!H:H,'Sales Record'!F:F,Sheet4!A2)=0,"",SUMIFS('Sales Record'!H:H,'Sales Record'!F:F,Sheet4!A2)) | E2: =IF(SUMIFS('Sales Return'!G:G,'Sales Return'!F:F,Sheet4!A2)=0,"",SUMIFS('Sales Return'!G:G,'Sales Return'!F:F,Sheet4!A2)) | F2: =IF(SUMIFS('Purchase Return'!G:G,'Purchase Return'!F:F,Sheet4!A2)=0,"",SUMIFS('Purchase Return'!G:G,'Purchase Return'!F:F,Sheet4!A2)) | G2: =IF(C2="","",N(C2)-N(D2)+N(E2)-N(F2)) -> 1
A3: =IF('Product List'!B3="","",'Product List'!B3) -> TB-002 | B3: =IF('Product List'!C3="","",'Product List'!C3) -> JW PIE Mini Hana - Black | C3: =IF(SUMIFS('Purchase Record'!G:G,'Purchase Record'!F:F,Sheet4!A3)=0,"",SUMIFS('Purchase Record'!G:G,'Purchase Record'!F:F,Sheet4!A3)) -> 2 | D3: =IF(SUMIFS('Sales Record'!H:H,'Sales Record'!F:F,Sheet4!A3)=0,"",SUMIFS('Sales Record'!H:H,'Sales Record'!F:F,Sheet4!A3)) -> 2 | E3: =IF(SUMIFS('Sales Return'!G:G,'Sales Return'!F:F,Sheet4!A3)=0,"",SUMIFS('Sales Return'!G:G,'Sales Return'!F:F,Sheet4!A3)) | F3: =IF(SUMIFS('Purchase Return'!G:G,'Purchase Return'!F:F,Sheet4!A3)=0,"",SUMIFS('Purchase Return'!G:G,'Purchase Return'!F:F,Sheet4!A3)) | G3: =IF(C3="","",N(C3)-N(D3)+N(E3)-N(F3)) -> 0
